#include <iostream>
#include <exception>
#include <stdexcept>
#include <cstdlib>

class Something {
  int x;
public:
  Something(int _x): x(_x) {
    std::cout << "Something(" << x << ")\n";
  }
  ~Something() {
    std::cout << "~Something(" << x << ")\n";
  }
};

int g(int a, int b) {
  Something(99);
  int divisor = a + b;
  if (divisor == 0) {
    throw std::domain_error("Division by zero");
  }
  return (a-b) / (divisor);
}

int f(int x) {
  int total = 0;
  Something(42); //为什么不是在报错后destruct，因为并非class而是那个玩意。。
  for (int i = 37; i <= 42; i++) {
    total += g (x, i);
  }
  return total;
}

int main(void) {
  Something s1(1);
  try {
    Something s2(7);
    Something (3);  //read this line carefully.....
    int answer = f(-40);
    std::cout << "The answer is " << answer << "\n";
  }
  catch (std::out_of_range & re) {
    std::cout << "A range exception (" << re.what() << ") occured!\n";
  }
  catch (std::domain_error & de ) {
    std::cout << "A domain error (" << de.what() << ") occured!\n";
  }
  catch (std::exception & e) {
    std::cout << "An exception (" << e.what() << " ) occured!\n";
  }
  std::cout << "At the end of main \n";
  return EXIT_SUCCESS;
}
